Workbook

Sheet Planilha1
A1: Grupo Pessoa | B1: e-mail
A2: 3B INDUSTRIA E COMERCIO LTDA | B2: sarah@3rsconfeccoes.com.br
A3: 3RS CONFECCOES LTDA | B3: sarah@3rsconfeccoes.com.br;charlene@3rsconfeccoes.com.br;danfe@3rsconfeccoes.com.br;contasapagar@3rsconfeccoes.com.br;charlene@floripatextil.com.br
A4: A RELA SA INDUSTRIA E COMERCIO | B4: eliete.catarina@gina.com.br
A5: ADIMIX INDUSTRIA E COMERCIO DE ADITIVOS PARA PANIFIC LT | B5: fiscal2@adimix.com.br;compras@adimix.com.br
A6: AGISTERELI COMERCIAL EIRELI | B6: mara@saggiodobrasil.com.br
A7: AKAZZO INDUSTRIA DE CALCADOS LTDA | B7: faturamento@akazzo.com.br
A8: ALCOFLAME IND COM PROD QUIM E MAQ LTDA | B8: jrenato@alcoflame.com.br
A9: ALE IND. MET. E PLASTICOS EIRELI | B9: faturamento@alegrete.net
A10: ALFAPET PRODUTOS PARA ANIMAIS LIMITADA | B10: adilson@alfapetgranulados.com.br
A11: ALIMENTOS TIA SONIA LTDA | B11: c.logistica@tiasonia.com.br;logistica4@tiasonia.com.br;logistica6@tiasonia.com.br
A12: AMENDO LOVERS INDUSTRIA E COMERCIO DE ALIMENTOS LTDA | B12: flavio.lellis@amendolovers.com.br;atendimento@amendolovers.com.br;anisio@amendolovers.com.br;marcia@amendolovers.com.br
... A274: VIVANT WINES INDUSTRIA E COMERCIO DE VINHOS SA | B274: andre@betterdrinks.com;nathalia.scott@vivantwines.com;paula@vivantwines.com;paula@vivantwines.com;carla.franca@vivantwines.com
A275: VKB ARTEFATOS DE LATEX LTDA
A276: VOLKMANN ALIMENTOS LTDA | B276: atendimento@volkmann.com.br
A277: VOLNEI DALCIN | B277: volneidalcin@gmail.com
A278: VOX INDUSTRIA E COMERCIO DE PLASTICOS EIRELI | B278: comercial@libertyplast.com.br;producao.ricardo@libertyplast.com.br;ADM@LIBERTYPLAST.COM.BR
A279: WEST GARDEN INDUSTRIA E COMERCIO LTDA | B279: elis.coelho@westgarden.com.br;financeiro@westgarden.com.br;nfe@westgarden.com.br;thais.alves@westgarden.com.br
A280: WORKSEG CONFECCOES E FERRAMENTAS LTDA
A281: Y.D. CONFECCOES LTDA | B281: marciorodrigues@callu.com.br

Sheet Planilha2
A1: Grupo Pessoa | B1: E-mail
A2: AMENDO LOVERS INDUSTRIA E COMERCIO DE ALIMENTOS LTDA | B2: =VLOOKUP(A2,Planilha1!A:B,2,0) -> flavio.lellis@amendolovers.com.br;atendimento@amendolovers.com.br;anisio@amendolovers.com.br;marcia@amendolovers.com.br
A3: ARTSANA BRASIL LTDA | B3: BR_Agendamentos@artsana.com>; leticia.lovato@artsana.com; Luiz.Costa@artsana.com>;
A4: EMCOMEX EMPRESA DE COMERCIO EXTERIOR LTDA | B4: =VLOOKUP(A4,Planilha1!A:B,2,0) -> apoiologistica2@buw.com.br;laianegabriel@buw.com.br;evandropazetto@buw.com.br
A5: BERBERT INDUSTRIA E COM DE ALI LTDA - EP | B5: =VLOOKUP(A5,Planilha1!A:B,2,0) -> biscoitofranbert@uol.com.br;juniorberbert@hotmail.com
A6: CONDOR S.A | B6: simone.santos@condor.ind.br; marlei.ganske@condor.ind.br
A7: SANTHER FABRICA DE P S T SA | B7: =VLOOKUP(A7,Planilha1!A:B,2,0) -> wendell.reis@santher.com.br;nfse@santher.com.br
A8: VIA VERNAGLIA MASSAS PREMIUM LTDA. | B8: pacheco.bemviver@gmail.com
A9: POLYPETRO IND E COM DE PLASTICOS LTDA | B9: gabriel@polypetro.com.br
A10: GSA GAMA SUCOS E ALIMENTOS LTDA. | B10: Sheila.Macedo@grupogsa.com.br; Marcelo.Souza@grupogsa.com.br; Wesley.Rodrigues@grupogsa.com.br
A11: ALIMENTOS TIA SONIA LTDA | B11: =VLOOKUP(A11,Planilha1!A:B,2,0) -> c.logistica@tiasonia.com.br;logistica4@tiasonia.com.br;logistica6@tiasonia.com.br
A12: INDUSTRIA DE TORRONE NOSSA SENHORA DE MONTEVERGINE LTDA | B12: =VLOOKUP(A12,Planilha1!A:B,2,0) -> transporte.mv@montevergine.com.br;edi.transporte@montevergine.com.br;valdelice.lopes@montevergine.com.br
A13: LIQUID BRANDS INDUSTRIA E COMERCIO | B13: =VLOOKUP(A13,Planilha1!A:B,2,0) -> financeiro@liquid.ind.br;thiago@liquid.ind.br
A14: BOMBRIL S.A | B14: camila.paiva@bombril.com.br; barbara.nicholli@bombril.com.br
A15: RECKITT BENCKISER (BRASIL) | B15: =VLOOKUP(A15,Planilha1!A:B,2,0) -> DocumentosNDD@rb.com
A16: ROCA PRONTA CONSERVAS E ANTEPASTOS EIRELI | B16: =VLOOKUP(A16,Planilha1!A:B,2,0) -> comercial@hortalica.com.br
A17: SUZANO S.A. | B17: =VLOOKUP(A17,Planilha1!A:B,2,0) -> nfs@suzano.com.br
A18: INGREDIENT INDUSTRIA E COMERCIO DE ALIMENTOS LTDA | B18: =VLOOKUP(A18,Planilha1!A:B,2,0) -> arnaldo@ingredient.com.br
A19: BARILLA DO BRASIL LTDA | B19: Helio.Canever@barilla.com; Adriano.Alves@barilla.com
A20: REAL COMERCIAL LTDA | B20: =VLOOKUP(A20,Planilha1!A:B,2,0) -> logistica@lapastina.com;jhonatan.beserra@grupolapastina.com.br;matheus.santos@grupolapastina.com.br;renato.perciani@grupolapastina.com.br
A21: A RELA SA INDUSTRIA E COMERCIO | B21: =VLOOKUP(A21,Planilha1!A:B,2,0) -> eliete.catarina@gina.com.br
A22: SOVENA BRASIL SERVICOS DE CONSULTORIA E COMERCIO DE ALIMENTO | B22: =VLOOKUP(A22,Planilha1!A:B,2,0) -> patricia.fernandes@sovena.com.br;accountspayable@sovena.com.br;andressa.passos@sovena.com.br;felipe.gevaerd@sovena.com.br;Alexander.lopes@sovena.com.br;rute.parreira@sovena.pt
A23: ALI-NUTRI INDUSTRIA, COMERCIO E IMPORTACAO LTDA | B23: vendas@alinutrialimentos.com.br
A24: PERFETTI VAN MELLE BRASIL LTDA. | B24: rogerio.cipriano@PerfettiVanMelle.com; rachel.castro@PerfettiVanMelle.com; sueli.souza@PerfettiVanMelle.com
A25: CRISTIANE NASCIMENTO PEREIRA ME | B25: =VLOOKUP(A25,Planilha1!A:B,2,0) -> matodoce@matodoce.com.br
A26: NILPAN IND E COM DE ADITIVOS E PRE MIST P/ PANIF LTDA | B26: faturamento@nilpan.com.br; jorge.cafe@nilpan.com.br; andre.meneses@nilpan.com.br
A27: PROCTER & GAMBLE INDUSTRIAL E COMERCIAL LTDA | B27: =VLOOKUP(A27,Planilha1!A:B,2,0) -> peg_nfe@nfe.ind.br;junior.o@pg.com
A28: AURORA BEBIDAS E ALIMENTOS FINOS LTDA | B28: bruna.arrais@aurora.com.br; anesio.junior@aurora.com.br
A29: MEGABRAYN DO BRASIL LTDA | B29: =VLOOKUP(A29,Planilha1!A:B,2,0) -> wallacy.souza@cafesantamonica.com.br;financeiro1@cafesantamonica.com.br;Logistica1@cafesantamonica.com.br;bispo@cafesantamonica.com.br
A30: SANAJ INDUSTRIAL LTDA | B30: dilene@sanaj.com.br; faturamento@sanaj.com.br
A31: MISASPEL COMERCIO DE PAPEIS LTDA
A32: MARCOS ART P PANIFICACAO LTDA | B32: =VLOOKUP(A32,Planilha1!A:B,2,0) -> ribeiropan2@gmail.com;recebimento@casadoconfeiteiro.com.br;grace.guin@casadoconfeiteiro.com.br;cr@casadoconfeiteiro.com.br
A33: BEG DESTILARIA COMERCIO E DISTRIBUICAO DE BEBIDAS- LTDA | B33: financeiro@beggin.com.br; aflosi@beggin.com.br
A34: BRG SUPLEMENTOS NUTRICIONAIS LTDA | B34: guilherme.lopes@integralmedica.com; ronei.santos@integralmedica.com
A35: INDUSTRIAS ANHEMBI LTDA | B35: stephanie.carneiro@anhembi.ind.br; gustavo.vianna@anhembi.ind.br
A36: MELHORAMENTOS PAPÉIS LTDA | B36: =VLOOKUP(A36,Planilha1!A:B,2,0) -> ahmata@softys.com
A37: TING INDUSTRIA E COMERCIO LTDA | B37: =VLOOKUP(A37,Planilha1!A:B,2,0) -> agendamento@ting.com.br
A38: COALA DO BRASIL LTDA | B38: auxlogistica@coala.com.br
A39: UTILITY HOUSE ARTEFATOS EMBALADOS LTDA | B39: =VLOOKUP(A39,Planilha1!A:B,2,0) -> faturamento@cicley.com.br
A40: GALAXY PARTICIPAÇÕES IMP E EXP LTDA | B40: milena.assis@galaxyled.com.br; logistica2@galaxyled.com.br;
...
